Workbook

Sheet Léeme
A1: CooperApp · Product Backlog 2026
A2: Tecnicatura en Desarrollo de Software · Prácticas Profesionalizantes 2 · 2°A · Grupo 3 (ABZ)
B5: EQUIPO
B6: Integrantes | C6: Aguilera Maximiliano · Hoyos Franco · Delipetro Ezequiel · Achille Nahuel
B7: Docente | C7: Mauro Ayala
B8: Repositorio | C8: github.com/NahuelAchille/cooperApp (rama test)
B10: CÓMO SE USA ESTE LIBRO
B11: Product Backlog | C11: Listado completo del proyecto ordenado por épica. Es la única fuente de verdad: si una historia cambia de estado, prioridad o sprint, se actualiza acá primero.
B12: Seguimiento | C12: Resumen de todos los sprints con cantidad de historias, tareas y porcentaje de avance. Se calcula solo.
B13: Sprint 01 a Sprint 13 | C13: Una hoja por sprint semanal. Cada lunes se trabaja sobre la hoja del sprint que arranca: se completan responsables y se van marcando estados. Si un sprint se extiende, no se crea una hoja nueva: se actualiza la existente y se corre el período de las siguientes.
B14: Incremento | C14: Qué queda funcionando al cerrar cada sprint y qué se le puede mostrar a un usuario real para pedir feedback.
B15: DOD | C15: Definición de Terminado acordada por el equipo. Una historia no se marca Hecho si no cumple todas las condiciones.
B16: Cambios vs. original | C16: Qué se modificó respecto del backlog entregado al docente anterior y por qué. Sirve para justificar la reorganización.
B18: RUTINA DE CADA LUNES
B19: 1. Cerrar el sprint anterior | C19: Marcar el estado real de cada tarea en la hoja del sprint que termina.
B20: 2. Revisar la DOD | C20: Verificar las condiciones de la hoja DOD para cada historia que se quiere dar por terminada.
B21: 3. Completar el Incremento | C21: Escribir en la hoja Incremento qué quedó funcionando y qué se puede mostrar.
B22: 4. Abrir el sprint nuevo | C22: Asignar responsables en la hoja del sprint que arranca y ajustar el alcance si quedó trabajo pendiente.
B23: 5. Sincronizar el Product Backlog | C23: Pasar los estados actualizados a la hoja Product Backlog.
B25: CONVENCIONES
B26: Identificadores | C26: E# = épica · HU-## = historia de usuario · T-##.# = tarea de una historia.
B27: Estados | C27: Pendiente · En curso · En revisión · Hecho · Bloqueado. Las celdas de estado tienen lista desplegable y se colorean solas.
B28: Capa MVP | C28: 1 = base indispensable · 2 = núcleo del MVP · 3 = completa el MVP · 4 = posterior al MVP.
B29: Sin estimación en horas | C29: El backlog no lleva horas: no hay velocidad real medida del equipo todavía. El avance se mide por tareas terminadas sobre tareas totales.

Sheet Product Backlog
A1: Product Backlog · CooperApp
A2: Listado completo del proyecto ordenado por épica · Fuente de verdad del equipo
A4: ID | B4: Tipo | C4: Épica | D4: Descripción | E4: Prioridad | F4: Capa MVP | G4: Sprint | H4: Estado | I4: Responsable
A5: E1 | B5: Épica | C5: Gestión de Empresas | D5: Registro, aprobación y administración del perfil de la empresa | E5: Alta
A6: HU-02 | B6: HU | C6: Gestión de Empresas | D6: Como empresa quiero registrarme en el sistema para solicitar el alta en la plataforma. | E6: Alta | F6: 1 | G6: Sprint 01 | H6: Hecho | I6: Equipo
A7: T-02.1 | B7: Tarea | D7: Diseñar el formulario de registro de empresa | F7: 1 | G7: Sprint 01 | H7: Hecho | I7: Equipo
A8: T-02.2 | B8: Tarea | D8: Programar el alta de la empresa en base de datos | F8: 1 | G8: Sprint 01 | H8: Hecho | I8: Equipo
A9: T-02.3 | B9: Tarea | D9: Programar el alta del usuario administrador en el mismo paso | F9: 1 | G9: Sprint 01 | H9: Hecho | I9: Equipo
A10: T-02.4 | B10: Tarea | D10: Implementar las validaciones de campos obligatorios y datos repetidos | F10: 1 | G10: Sprint 01 | H10: Hecho | I10: Equipo
A11: T-02.5 | B11: Tarea | D11: Dejar la empresa en estado pendiente | F11: 1 | G11: Sprint 01 | H11: Hecho | I11: Equipo
A12: T-02.6 | B12: Tarea | D12: Pruebas funcionales del registro | F12: 1 | G12: Sprint 01 | H12: Hecho | I12: Equipo
A13: HU-03 | B13: HU | C13: Gestión de Empresas | D13: Como administrador de la plataforma quiero aprobar o rechazar empresas para controlar quién accede. | E13: Alta | F13: 1 | G13: Sprint 01 | H13: Hecho | I13: Equipo
A14: T-03.1 | B14: Tarea | D14: Diseñar el panel de administración de la plataforma | F14: 1 | G14: Sprint 01 | H14: Hecho | I14: Equipo
A15: T-03.2 | B15: Tarea | D15: Programar el listado de empresas pendientes | F15: 1 | G15: Sprint 01 | H15: Hecho | I15: Equipo
A16: T-03.3 | B16: Tarea | D16: Programar el listado de todas las empresas | F16: 1 | G16: Sprint 01 | H16: Hecho | I16: Equipo
A17: T-03.4 | B17: Tarea | D17: Programar los endpoints de aprobar y rechazar | F17: 1 | G17: Sprint 01 | H17: Hecho | I17: Equipo
A18: T-03.5 | B18: Tarea | D18: Activar el usuario administrador al aprobar la empresa | F18: 1 | G18: Sprint 01 | H18: Hecho | I18: Equipo
A19: T-03.6 | B19: Tarea | D19: Pruebas del circuito de aprobación | F19: 1 | G19: Sprint 01 | H19: Hecho | I19: Equipo
A20: HU-09 | B20: HU | C20: Gestión de Empresas | D20: Como administrador de la empresa quiero editar los datos de mi empresa para mantenerlos actualizados. | E20: Alta | F20: 1 | G20: Sprint 03 | H20: Hecho | I20: Equipo
A21: T-09.1 | B21: Tarea | D21: Programar las consultas de búsqueda y actualización de la empresa | F21: 1 | G21: Sprint 03 | H21: Hecho | I21: Equipo
A22: T-09.2 | B22: Tarea | D22: Programar los endpoints de consulta y edición | F22: 1 | G22: Sprint 03 | H22: Hecho | I22: Equipo
A23: T-09.3 | B23: Tarea | D23: Diseñar la pantalla de perfil de la empresa | F23: 1 | G23: Sprint 03 | H23: Hecho | I23: Equipo
A24: T-09.4 | B24: Tarea | D24: Validar que el email no se repita con el de otra empresa | F24: 1 | G24: Sprint 03 | H24: Hecho | I24: Equipo
A25: T-09.5 | B25: Tarea | D25: Agregar el acceso en el menú | F25: 1 | G25: Sprint 03 | H25: Hecho | I25: Equipo
A26: HU-32 | B26: HU | C26: Gestión de Empresas | D26: Como equipo quiero renombrar el dominio de cooperativas a empresas para que el sistema hable el idioma del público nuevo. | E26: Alta | F26: 2 | G26: Sprint 06 | H26: Hecho | I26: Equipo
A27: T-32.1 | B27: Tarea | D27: Renombrar las tablas y columnas en el script de base de datos | F27: 2 | G27: Sprint 06 | H27: Hecho | I27: Equipo
A28: T-32.2 | B28: Tarea | D28: Renombrar el rol de administrador de empresa | F28: 2 | G28: Sprint 06 | H28: Hecho | I28: Equipo
A29: T-32.3 | B29: Tarea | D29: Renombrar modelos, controladores, rutas y vistas | F29: 2 | G29: Sprint 06 | H29: Hecho | I29: Equipo
A30: T-32.4 | B30: Tarea | D30: Actualizar los datos de prueba con empresas y vocabulario acorde | F30: 2 | G30: Sprint 06 | H30: Hecho | I30: Equipo
A31: T-32.5 | B31: Tarea | D31: Verificar los circuitos completos después del renombrado | F31: 2 | G31: Sprint 06 | H31: Hecho | I31: Equipo
A32: HU-72 | B32: HU | C32: Gestión de Empresas | D32: Como empresa quiero verificar mi correo al registrarme para validar mi identidad. | E32: Baja | F32: 4 | G32: Sin asignar | H32: Pendiente
A33: T-72.1 | B33: Tarea | D33: Programar el token de verificación | F33: 4 | G33: Sin asignar | H33: Pendiente
A34: T-72.2 | B34: Tarea | D34: Programar el envío del correo de verificación | F34: 4 | G34: Sin asignar | H34: Pendiente
A35: T-72.3 | B35: Tarea | D35: Programar el endpoint de confirmación | F35: 4 | G35: Sin asignar | H35: Pendiente
A36: HU-76 | B36: HU | C36: Gestión de Empresas | D36: Como equipo quiero redefinir los campos heredados del modelo cooperativo para que tengan sentido en una empresa. | E36: Media | F36: 4 | G36: Sin asignar | H36: Pendiente
A37: T-76.1 | B37: Tarea | D37: Definir el equivalente de matrícula y federación para una empresa | F37: 4 | G37: Sin asignar | H37: Pendiente
A38: T-76.2 | B38: Tarea | D38: Migrar o eliminar los campos del modelo | F38: 4 | G38: Sin asignar | H38: Pendiente
A39: T-76.3 | B39: Tarea | D39: Actualizar el formulario de registro y el perfil | F39: 4 | G39: Sin asignar | H39: Pendiente
A40: E2 | B40: Épica | C40: Usuarios, Roles y Permisos | D40: Alta, baja y modificación de usuarios; control de acceso por rol | E40: Alta
A41: HU-05 | B41: HU | C41: Usuarios, Roles y Permisos | D41: Como usuario quiero iniciar sesión para acceder a mi cuenta. | E41: Alta | F41: 1 | G41: Sprint 02 | H41: Hecho | I41: Equipo
...

Sheet Seguimiento
A1: Seguimiento de Sprints · CooperApp
A2: Se calcula automáticamente a partir de las hojas de cada sprint
A4: Sprint | B4: Período | C4: Objetivo | D4: HU | E4: Tareas | F4: Tareas hechas | G4: % Avance | H4: Estado
A5: Sprint 01 | B5: Cerrado · entrega anterior | C5: Modelo de datos inicial y circuito de alta de empresas: una empresa se registra y el administrador de la plataforma la aprueba o la rechaza. | D5: 4 | E5: =SUMPRODUCT((LEFT('Sprint 01'!A6:A28,2)="T-")*1) | F5: =SUMPRODUCT((LEFT('Sprint 01'!A6:A28,2)="T-")*('Sprint 01'!E6:E28="Hecho")) | G5: =IF(E5=0,0,F5/E5) | H5: Cerrado
A6: Sprint 02 | B6: Cerrado · entrega anterior | C6: Acceso al sistema y gestión de usuarios: inicio de sesión, contraseña temporal en el primer ingreso, alta de usuarios por parte del administrador y control de acceso por rol. | D6: 4 | E6: =SUMPRODUCT((LEFT('Sprint 02'!A6:A27,2)="T-")*1) | F6: =SUMPRODUCT((LEFT('Sprint 02'!A6:A27,2)="T-")*('Sprint 02'!E6:E27="Hecho")) | G6: =IF(E6=0,0,F6/E6) | H6: Cerrado
A7: Sprint 03 | B7: 24/08 al 30/08 | C7: Cerrar el módulo de acceso con lo que faltaba: perfil de la empresa, reseteo de contraseñas por el administrador y limpieza de la estructura de roles. | D7: 9 | E7: =SUMPRODUCT((LEFT('Sprint 03'!A6:A50,2)="T-")*1) | F7: =SUMPRODUCT((LEFT('Sprint 03'!A6:A50,2)="T-")*('Sprint 03'!E6:E50="Hecho")) | G7: =IF(E7=0,0,F7/E7) | H7: Cerrado
A8: Sprint 04 | B8: 31/08 al 06/09 | C8: Construir la estructura de clasificación de ingresos y egresos, que es la base sobre la que se apoyan los movimientos y los reportes. | D8: 4 | E8: =SUMPRODUCT((LEFT('Sprint 04'!A6:A23,2)="T-")*1) | F8: =SUMPRODUCT((LEFT('Sprint 04'!A6:A23,2)="T-")*('Sprint 04'!E6:E23="Hecho")) | G8: =IF(E8=0,0,F8/E8) | H8: Cerrado
A9: Sprint 05 | B9: 07/09 al 13/09 | C9: Registrar, consultar y corregir ingresos y egresos, y mostrar el resumen económico con datos reales en el dashboard. Es la funcionalidad central del MVP. | D9: 9 | E9: =SUMPRODUCT((LEFT('Sprint 05'!A6:A45,2)="T-")*1) | F9: =SUMPRODUCT((LEFT('Sprint 05'!A6:A45,2)="T-")*('Sprint 05'!E6:E45="Hecho")) | G9: =IF(E9=0,0,F9/E9) | H9: Cerrado
A10: Sprint 06 | B10: 14/09 al 20/09 | C10: Absorber el cambio de rumbo: el producto pasa a ofrecerse a empresas en general. Corregir la deuda detectada en la revisión, renombrar el dominio y habilitar que cada empresa active sólo los módulos que usa. | D10: 6 | E10: =SUMPRODUCT((LEFT('Sprint 06'!A6:A40,2)="T-")*1) | F10: =SUMPRODUCT((LEFT('Sprint 06'!A6:A40,2)="T-")*('Sprint 06'!E6:E40="Hecho")) | G10: =IF(E10=0,0,F10/E10) | H10: Cerrado
A11: Sprint 07 | B11: 21/09 al 27/09 | C11: Abrir el módulo de Productos: que cada empresa arme su propio árbol de categorías y subcategorías y cargue su catálogo. | D11: 4 | E11: =SUMPRODUCT((LEFT('Sprint 07'!A6:A22,2)="T-")*1) | F11: =SUMPRODUCT((LEFT('Sprint 07'!A6:A22,2)="T-")*('Sprint 07'!E6:E22="Hecho")) | G11: =IF(E11=0,0,F11/E11) | H11: Cerrado
A12: Sprint 08 | B12: 28/09 al 04/10 | C12: Cerrar el módulo de Productos con el control de existencias: motivos configurables, registro de movimientos de stock y aviso de faltantes. | D12: 6 | E12: =SUMPRODUCT((LEFT('Sprint 08'!A6:A31,2)="T-")*1) | F12: =SUMPRODUCT((LEFT('Sprint 08'!A6:A31,2)="T-")*('Sprint 08'!E6:E31="Hecho")) | G12: =IF(E12=0,0,F12/E12) | H12: Cerrado
A13: Sprint 09 | B13: 05/10 al 11/10 | C13: Emparejar la base ANTES de duplicarla, y recién entonces abrir Servicios. El orden importa: Servicios copia las pantallas de Productos, así que cada nombre, cada tabla que no entra en el celular y cada pantalla de configuración mal ubicada que quede sin arreglar se copia a un lugar más. Primero el vocabulario, el celular y la configuración; después el módulo nuevo, que es un producto sin stock. | D13: 9 | E13: =SUMPRODUCT((LEFT('Sprint 09'!A6:A52,2)="T-")*1) | F13: =SUMPRODUCT((LEFT('Sprint 09'!A6:A52,2)="T-")*('Sprint 09'!E6:E52="Hecho")) | G13: =IF(E13=0,0,F13/E13) | H13: En curso
A14: Sprint 10 | B14: 12/10 al 18/10 | C14: Entregar los reportes por período, categoría, producto y servicio, con exportación para que la empresa pueda compartirlos fuera del sistema. | D14: 4 | E14: =SUMPRODUCT((LEFT('Sprint 10'!A6:A22,2)="T-")*1) | F14: =SUMPRODUCT((LEFT('Sprint 10'!A6:A22,2)="T-")*('Sprint 10'!E6:E22="Hecho")) | G14: =IF(E14=0,0,F14/E14) | H14: En curso
A15: Sprint 11 | B15: 19/10 al 25/10 | C15: Abrir el segundo eje del proyecto: que las empresas publiquen sus necesidades y lo que pueden ofrecer, para habilitar la articulación entre ellas. | D15: 4 | E15: =SUMPRODUCT((LEFT('Sprint 11'!A6:A18,2)="T-")*1) | F15: =SUMPRODUCT((LEFT('Sprint 11'!A6:A18,2)="T-")*('Sprint 11'!E6:E18="Hecho")) | G15: =IF(E15=0,0,F15/E15) | H15: Planificado
A16: Sprint 12 | B16: 26/10 al 01/11 | C16: Completar la articulación con la detección automática de coincidencias y el aviso de match, que es la funcionalidad diferencial del producto. | D16: 4 | E16: =SUMPRODUCT((LEFT('Sprint 12'!A6:A18,2)="T-")*1) | F16: =SUMPRODUCT((LEFT('Sprint 12'!A6:A18,2)="T-")*('Sprint 12'!E6:E18="Hecho")) | G16: =IF(E16=0,0,F16/E16) | H16: Planificado
A17: Sprint 13 | B17: 02/11 al 08/11 | C17: Cierre del ciclo: definir la identidad del producto, terminar de ajustar la interfaz, probar de punta a punta y documentar para la continuidad del proyecto. Queda más liviano que en la planificación anterior porque el vocabulario, el celular y la configuración se adelantaron al Sprint 09, donde hacían falta. | D17: 7 | E17: =SUMPRODUCT((LEFT('Sprint 13'!A6:A37,2)="T-")*1) | F17: =SUMPRODUCT((LEFT('Sprint 13'!A6:A37,2)="T-")*('Sprint 13'!E6:E37="Hecho")) | G17: =IF(E17=0,0,F17/E17) | H17: Planificado
C18: TOTAL DEL PROYECTO | D18: =SUM(D5:D17) | E18: =SUM(E5:E17) | F18: =SUM(F5:F17) | G18: =IF(E18=0,0,F18/E18)

Sheet Sprint 01
A1: Sprint 01 · CooperApp
A2: Período: Cerrado · entrega anterior | Estado: Cerrado
A3: Objetivo del sprint: Modelo de datos inicial y circuito de alta de empresas: una empresa se registra y el administrador de la plataforma la aprueba o la rechaza.
A5: ID | B5: Historia de usuario / Tarea | C5: Épica | D5: Responsable | E5: Estado
A6: HU-01 | B6: Como equipo técnico quiero contar con el modelo de datos inicial para sostener los módulos del sistema. | C6: Base de Datos e Infraestructura | D6: Equipo | E6: Hecho
A7: T-01.1 | B7: Diseñar el DER inicial del sistema | D7: Equipo | E7: Hecho
A8: T-01.2 | B8: Escribir el script SQL de creación de tablas | D8: Equipo | E8: Hecho
A9: T-01.3 | B9: Cargar los datos iniciales de roles y permisos | D9: Equipo | E9: Hecho
A10: T-01.4 | B10: Configurar la conexión a MySQL desde Node | D10: Equipo | E10: Hecho
A11: HU-02 | B11: Como empresa quiero registrarme en el sistema para solicitar el alta en la plataforma. | C11: Gestión de Empresas | D11: Equipo | E11: Hecho
A12: T-02.1 | B12: Diseñar el formulario de registro de empresa | D12: Equipo | E12: Hecho
A13: T-02.2 | B13: Programar el alta de la empresa en base de datos | D13: Equipo | E13: Hecho
A14: T-02.3 | B14: Programar el alta del usuario administrador en el mismo paso | D14: Equipo | E14: Hecho
A15: T-02.4 | B15: Implementar las validaciones de campos obligatorios y datos repetidos | D15: Equipo | E15: Hecho
A16: T-02.5 | B16: Dejar la empresa en estado pendiente | D16: Equipo | E16: Hecho
A17: T-02.6 | B17: Pruebas funcionales del registro | D17: Equipo | E17: Hecho
A18: HU-03 | B18: Como administrador de la plataforma quiero aprobar o rechazar empresas para controlar quién accede. | C18: Gestión de Empresas | D18: Equipo | E18: Hecho
A19: T-03.1 | B19: Diseñar el panel de administración de la plataforma | D19: Equipo | E19: Hecho
A20: T-03.2 | B20: Programar el listado de empresas pendientes | D20: Equipo | E20: Hecho
A21: T-03.3 | B21: Programar el listado de todas las empresas | D21: Equipo | E21: Hecho
A22: T-03.4 | B22: Programar los endpoints de aprobar y rechazar | D22: Equipo | E22: Hecho
A23: T-03.5 | B23: Activar el usuario administrador al aprobar la empresa | D23: Equipo | E23: Hecho
A24: T-03.6 | B24: Pruebas del circuito de aprobación | D24: Equipo | E24: Hecho
A25: HU-04 | B25: Como equipo quiero una maqueta del dashboard para validar la propuesta visual. | C25: Calidad, UX y Documentación | D25: Equipo | E25: Hecho
A26: T-04.1 | B26: Definir la paleta y los estilos base del sistema | D26: Equipo | E26: Hecho
A27: T-04.2 | B27: Maquetar el dashboard con datos de ejemplo | D27: Equipo | E27: Hecho
A28: T-04.3 | B28: Maquetar el encabezado y el menú de navegación | D28: Equipo | E28: Hecho
C30: AVANCE DEL SPRINT (tareas terminadas) | E30: =TEXT(SUMPRODUCT((LEFT(A6:A28,2)="T-")*(E6:E28="Hecho"))/SUMPRODUCT((LEFT(A6:A28,2)="T-")*1),"0%")

Sheet Sprint 02
A1: Sprint 02 · CooperApp
A2: Período: Cerrado · entrega anterior | Estado: Cerrado
A3: Objetivo del sprint: Acceso al sistema y gestión de usuarios: inicio de sesión, contraseña temporal en el primer ingreso, alta de usuarios por parte del administrador y control de acceso por rol.
A5: ID | B5: Historia de usuario / Tarea | C5: Épica | D5: Responsable | E5: Estado
A6: HU-05 | B6: Como usuario quiero iniciar sesión para acceder a mi cuenta. | C6: Usuarios, Roles y Permisos | D6: Equipo | E6: Hecho
A7: T-05.1 | B7: Diseñar la pantalla de inicio de sesión | D7: Equipo | E7: Hecho
A8: T-05.2 | B8: Implementar la autenticación con contraseña encriptada | D8: Equipo | E8: Hecho
A9: T-05.3 | B9: Implementar el manejo de sesiones | D9: Equipo | E9: Hecho
A10: T-05.4 | B10: Validar el estado de la empresa antes de permitir el acceso | D10: Equipo | E10: Hecho
A11: T-05.5 | B11: Pruebas de acceso y seguridad básica | D11: Equipo | E11: Hecho
A12: HU-06 | B12: Como usuario nuevo quiero cambiar mi contraseña temporal en el primer ingreso para asegurar mi cuenta. | C12: Usuarios, Roles y Permisos | D12: Equipo | E12: Hecho
A13: T-06.1 | B13: Diseñar la pantalla de cambio de contraseña | D13: Equipo | E13: Hecho
A14: T-06.2 | B14: Programar la detección del primer ingreso | D14: Equipo | E14: Hecho
A15: T-06.3 | B15: Validar la fortaleza de la contraseña nueva | D15: Equipo | E15: Hecho
A16: T-06.4 | B16: Redirigir al sistema una vez cambiada | D16: Equipo | E16: Hecho
A17: HU-07 | B17: Como administrador de la empresa quiero crear usuarios y asignarles un rol para que mi equipo opere el sistema. | C17: Usuarios, Roles y Permisos | D17: Equipo | E17: Hecho
A18: T-07.1 | B18: Diseñar el panel de gestión de usuarios | D18: Equipo | E18: Hecho
A19: T-07.2 | B19: Programar el alta de usuario con contraseña temporal | D19: Equipo | E19: Hecho
A20: T-07.3 | B20: Programar la asignación de rol | D20: Equipo | E20: Hecho
A21: T-07.4 | B21: Programar el listado de usuarios de la empresa | D21: Equipo | E21: Hecho
A22: T-07.5 | B22: Validar que no se repitan email ni DNI | D22: Equipo | E22: Hecho
A23: HU-08 | B23: Como sistema quiero restringir las acciones según el rol del usuario para proteger la información. | C23: Usuarios, Roles y Permisos | D23: Equipo | E23: Hecho
A24: T-08.1 | B24: Programar el middleware de sesión activa | D24: Equipo | E24: Hecho
A25: T-08.2 | B25: Programar el middleware de validación de rol | D25: Equipo | E25: Hecho
A26: T-08.3 | B26: Aplicar los middlewares a las rutas protegidas | D26: Equipo | E26: Hecho
A27: T-08.4 | B27: Ocultar en la interfaz las opciones según el rol | D27: Equipo | E27: Hecho
C29: AVANCE DEL SPRINT (tareas terminadas) | E29: =TEXT(SUMPRODUCT((LEFT(A6:A27,2)="T-")*(E6:E27="Hecho"))/SUMPRODUCT((LEFT(A6:A27,2)="T-")*1),"0%")

Sheet Sprint 03
A1: Sprint 03 · CooperApp
A2: Período: 24/08 al 30/08 | Estado: Cerrado
A3: Objetivo del sprint: Cerrar el módulo de acceso con lo que faltaba: perfil de la empresa, reseteo de contraseñas por el administrador y limpieza de la estructura de roles.
A5: ID | B5: Historia de usuario / Tarea | C5: Épica | D5: Responsable | E5: Estado
A6: HU-09 | B6: Como administrador de la empresa quiero editar los datos de mi empresa para mantenerlos actualizados. | C6: Gestión de Empresas | D6: Equipo | E6: Hecho
A7: T-09.1 | B7: Programar las consultas de búsqueda y actualización de la empresa | D7: Equipo | E7: Hecho
A8: T-09.2 | B8: Programar los endpoints de consulta y edición | D8: Equipo | E8: Hecho
A9: T-09.3 | B9: Diseñar la pantalla de perfil de la empresa | D9: Equipo | E9: Hecho
A10: T-09.4 | B10: Validar que el email no se repita con el de otra empresa | D10: Equipo | E10: Hecho
A11: T-09.5 | B11: Agregar el acceso en el menú | D11: Equipo | E11: Hecho
A12: HU-10 | B12: Como administrador de la plataforma quiero resetear la contraseña de un administrador de empresa para desbloquearlo sin depender del correo. | C12: Usuarios, Roles y Permisos | D12: Equipo | E12: Hecho
A13: T-10.1 | B13: Programar el endpoint de reseteo | D13: Equipo | E13: Hecho
A14: T-10.2 | B14: Agregar el botón en el panel de la plataforma | D14: Equipo | E14: Hecho
A15: T-10.3 | B15: Forzar el cambio de contraseña en el próximo ingreso | D15: Equipo | E15: Hecho
A16: HU-11 | B16: Como administrador de la empresa quiero resetear la contraseña de un usuario de mi equipo para desbloquearlo en el momento. | C16: Usuarios, Roles y Permisos | D16: Equipo | E16: Hecho
A17: T-11.1 | B17: Programar las reglas de permiso del reseteo | D17: Equipo | E17: Hecho
A18: T-11.2 | B18: Agregar el botón en la pantalla de usuarios | D18: Equipo | E18: Hecho
A19: T-11.3 | B19: Probar las reglas de permiso | D19: Equipo | E19: Hecho
A20: HU-12 | B20: Como equipo quiero quitar la empresa ficticia asociada al administrador de la plataforma para que la estructura de roles sea coherente. | C20: Base de Datos e Infraestructura | D20: Equipo | E20: Hecho
A21: T-12.1 | B21: Quitar la empresa ficticia del script de base de datos | D21: Equipo | E21: Hecho
A22: T-12.2 | B22: Dejar la referencia a empresa vacía para el administrador de plataforma | D22: Equipo | E22: Hecho
A23: T-12.3 | B23: Verificar que no se vea a sí mismo en su panel | D23: Equipo | E23: Hecho
A24: HU-13 | B24: Como administrador de la empresa quiero editar y dar de baja usuarios para mantener el equipo actualizado. | C24: Usuarios, Roles y Permisos | D24: Equipo | E24: Hecho
A25: T-13.1 | B25: Programar el endpoint de edición de usuario | D25: Equipo | E25: Hecho
A26: T-13.2 | B26: Programar el endpoint de baja lógica | D26: Equipo | E26: Hecho
A27: T-13.3 | B27: Agregar los botones en el listado de usuarios | D27: Equipo | E27: Hecho
A28: T-13.4 | B28: Extraer las reglas de permiso a una función común | D28: Equipo | E28: Hecho
A29: T-13.5 | B29: Probar las reglas de permiso | D29: Equipo | E29: Hecho
A30: HU-14 | B30: Como equipo quiero renombrar la columna de contraseña para que el script SQL se importe sin problemas de codificación. | C30: Base de Datos e Infraestructura | D30: Equipo | E30: Hecho
A31: T-14.1 | B31: Renombrar la columna en el script de base de datos | D31: Equipo | E31: Hecho
A32: T-14.2 | B32: Actualizar las consultas del modelo de usuarios | D32: Equipo | E32: Hecho
A33: T-14.3 | B33: Actualizar los controladores afectados | D33: Equipo | E33: Hecho
A34: T-14.4 | B34: Verificar la importación desde cero | D34: Equipo | E34: Hecho
A35: T-14.5 | B35: Probar los circuitos que tocan contraseñas | D35: Equipo | E35: Hecho
A36: HU-15 | B36: Como sistema quiero proteger las consultas de empresas para que nadie sin sesión vea ni modifique el listado. | C36: Usuarios, Roles y Permisos | D36: Equipo | E36: Hecho
A37: T-15.1 | B37: Agregar los middlewares a las rutas de empresas | D37: Equipo | E37: Hecho
A38: T-15.2 | B38: Desviar al login cuando no hay sesión | D38: Equipo | E38: Hecho
A39: T-15.3 | B39: Desviar al dashboard cuando el rol no corresponde | D39: Equipo | E39: Hecho
A40: T-15.4 | B40: Probar el acceso sin sesión y con rol incorrecto | D40: Equipo | E40: Hecho
A41: HU-16 | B41: Como sistema quiero validar el rol que se asigna al crear un usuario para evitar una escalada de privilegios. | C41: Usuarios, Roles y Permisos | D41: Equipo | E41: Hecho
...

Sheet Sprint 04
A1: Sprint 04 · CooperApp
A2: Período: 31/08 al 06/09 | Estado: Cerrado
A3: Objetivo del sprint: Construir la estructura de clasificación de ingresos y egresos, que es la base sobre la que se apoyan los movimientos y los reportes.
A5: ID | B5: Historia de usuario / Tarea | C5: Épica | D5: Responsable | E5: Estado
A6: HU-18 | B6: Como administrador quiero gestionar las categorías de ingresos y egresos para clasificar los movimientos. | C6: Estructura de Categorías | D6: Equipo | E6: Hecho
A7: T-18.1 | B7: Crear la tabla de categorías en la base de datos | D7: Equipo | E7: Hecho
A8: T-18.2 | B8: Programar los endpoints de alta, edición y cambio de estado | D8: Equipo | E8: Hecho
A9: T-18.3 | B9: Diseñar la pantalla de gestión de categorías | D9: Equipo | E9: Hecho
A10: T-18.4 | B10: Validar el nombre único por empresa y naturaleza | D10: Equipo | E10: Hecho
A11: HU-19 | B11: Como administrador quiero gestionar los tipos dentro de cada categoría para clasificar con mayor detalle. | C11: Estructura de Categorías | D11: Equipo | E11: Hecho
A12: T-19.1 | B12: Crear la tabla de tipos con su clave foránea | D12: Equipo | E12: Hecho
A13: T-19.2 | B13: Programar los endpoints de tipos | D13: Equipo | E13: Hecho
A14: T-19.3 | B14: Diseñar la pantalla anidada de categorías y tipos | D14: Equipo | E14: Hecho
A15: T-19.4 | B15: Implementar las validaciones | D15: Equipo | E15: Hecho
A16: HU-20 | B16: Como sistema quiero que la naturaleza de una categoría no se pueda cambiar para no romper el historial. | C16: Estructura de Categorías | D16: Equipo | E16: Hecho
A17: T-20.1 | B17: Definir la naturaleza como dato fijo de la categoría | D17: Equipo | E17: Hecho
A18: T-20.2 | B18: Permitir únicamente el renombrado en la edición | D18: Equipo | E18: Hecho
A19: HU-21 | B19: Como sistema quiero impedir la eliminación de categorías con movimientos asociados para no perder información histórica. | C19: Estructura de Categorías | D19: Equipo | E19: Hecho
A20: T-21.1 | B20: Implementar la baja lógica de categorías y tipos | D20: Equipo | E20: Hecho
A21: T-21.2 | B21: Programar la cascada de estado hacia los tipos | D21: Equipo | E21: Hecho
A22: T-21.3 | B22: Impedir el uso de tipos y categorías desactivados | D22: Equipo | E22: Hecho
A23: T-21.4 | B23: Pruebas de la regla | D23: Equipo | E23: Hecho
C25: AVANCE DEL SPRINT (tareas terminadas) | E25: =TEXT(SUMPRODUCT((LEFT(A6:A23,2)="T-")*(E6:E23="Hecho"))/SUMPRODUCT((LEFT(A6:A23,2)="T-")*1),"0%")

Sheet Sprint 05
A1: Sprint 05 · CooperApp
A2: Período: 07/09 al 13/09 | Estado: Cerrado
A3: Objetivo del sprint: Registrar, consultar y corregir ingresos y egresos, y mostrar el resumen económico con datos reales en el dashboard. Es la funcionalidad central del MVP.
A5: ID | B5: Historia de usuario / Tarea | C5: Épica | D5: Responsable | E5: Estado
A6: HU-22 | B6: Como tesorero quiero registrar un ingreso o un egreso para llevar el control del dinero de la empresa. | C6: Movimientos Económico-Financieros | D6: Equipo | E6: Hecho
A7: T-22.1 | B7: Rediseñar la tabla de movimientos con el nuevo esquema de clasificación | D7: Equipo | E7: Hecho
A8: T-22.2 | B8: Diseñar el formulario de registro en un solo paso | D8: Equipo | E8: Hecho
A9: T-22.3 | B9: Programar el endpoint de alta de movimiento | D9: Equipo | E9: Hecho
A10: T-22.4 | B10: Encadenar los selectores de naturaleza, categoría y tipo | D10: Equipo | E10: Hecho
A11: HU-23 | B11: Como usuario con poca experiencia digital quiero un formulario simple para no equivocarme al cargar. | C11: Movimientos Económico-Financieros | D11: Equipo | E11: Hecho
A12: T-23.1 | B12: Diseñar el formulario en un solo paso | D12: Equipo | E12: Hecho
A13: T-23.2 | B13: Proponer la fecha de hoy por defecto | D13: Equipo | E13: Hecho
A14: T-23.3 | B14: Redactar los mensajes de error en lenguaje claro | D14: Equipo | E14: Hecho
A15: HU-24 | B15: Como empresa quiero saber quién cargó cada movimiento para tener trazabilidad. | C15: Movimientos Económico-Financieros | D15: Equipo | E15: Hecho
A16: T-24.1 | B16: Guardar el usuario y la marca de tiempo en cada movimiento | D16: Equipo | E16: Hecho
A17: T-24.2 | B17: Mostrar quién lo cargó en el listado | D17: Equipo | E17: Hecho
A18: HU-25 | B18: Como usuario quiero ver y filtrar el listado de movimientos para encontrar lo que busco. | C18: Movimientos Económico-Financieros | D18: Equipo | E18: Hecho
A19: T-25.1 | B19: Programar el listado con filtros combinables | D19: Equipo | E19: Hecho
A20: T-25.2 | B20: Diseñar la tabla de movimientos | D20: Equipo | E20: Hecho
A21: T-25.3 | B21: Diseñar los controles de filtro | D21: Equipo | E21: Hecho
A22: T-25.4 | B22: Implementar el filtro por rango de fechas | D22: Equipo | E22: Hecho
A23: HU-26 | B23: Como tesorero quiero anular un movimiento cargado por error para mantener la información confiable. | C23: Movimientos Económico-Financieros | D23: Equipo | E23: Hecho
A24: T-26.1 | B24: Programar la anulación lógica | D24: Equipo | E24: Hecho
A25: T-26.2 | B25: Excluir los anulados de los totales | D25: Equipo | E25: Hecho
A26: T-26.3 | B26: Agregar el filtro para ver los anulados | D26: Equipo | E26: Hecho
A27: T-26.4 | B27: Diseñar la confirmación con explicación clara | D27: Equipo | E27: Hecho
A28: HU-27 | B28: Como empresa quiero ver el balance entre ingresos y egresos para conocer mi situación económica. | C28: Resumen Económico | D28: Equipo | E28: Hecho
A29: T-27.1 | B29: Programar la consulta de agregación de montos | D29: Equipo | E29: Hecho
A30: T-27.2 | B30: Programar el endpoint de resumen | D30: Equipo | E30: Hecho
A31: T-27.3 | B31: Diseñar las tarjetas de ingresos, egresos y balance | D31: Equipo | E31: Hecho
A32: T-27.4 | B32: Hacer que el resumen respete los mismos filtros que el listado | D32: Equipo | E32: Hecho
A33: HU-28 | B33: Como empresa quiero ver el resumen del mes comparado con el anterior para seguir mi evolución. | C33: Resumen Económico | D33: Equipo | E33: Hecho
A34: T-28.1 | B34: Programar el cálculo del rango del mes | D34: Equipo | E34: Hecho
A35: T-28.2 | B35: Programar la comparación con el mes anterior | D35: Equipo | E35: Hecho
A36: T-28.3 | B36: Diseñar los indicadores del dashboard | D36: Equipo | E36: Hecho
A37: HU-29 | B37: Como usuario quiero que el dashboard muestre los datos reales de mi empresa. | C37: Resumen Económico | D37: Equipo | E37: Hecho
A38: T-29.1 | B38: Reemplazar los datos de ejemplo del dashboard | D38: Equipo | E38: Hecho
A39: T-29.2 | B39: Mostrar los movimientos recientes reales | D39: Equipo | E39: Hecho
A40: T-29.3 | B40: Mostrar la cantidad de usuarios activos | D40: Equipo | E40: Hecho
A41: T-29.4 | B41: Diseñar el estado vacío sin datos | D41: Equipo | E41: Hecho
...

Sheet Sprint 06
A1: Sprint 06 · CooperApp
A2: Período: 14/09 al 20/09 | Estado: Cerrado
A3: Objetivo del sprint: Absorber el cambio de rumbo: el producto pasa a ofrecerse a empresas en general. Corregir la deuda detectada en la revisión, renombrar el dominio y habilitar que cada empresa active sólo los módulos que usa.
A5: ID | B5: Historia de usuario / Tarea | C5: Épica | D5: Responsable | E5: Estado
A6: HU-31 | B6: Como equipo quiero corregir los errores detectados en la revisión del módulo de movimientos para entregarlo confiable. | C6: Calidad, UX y Documentación | D6: Equipo | E6: Hecho
A7: T-31.1 | B7: Escapar los textos del usuario en las pantallas que faltaban | D7: Equipo | E7: Hecho
A8: T-31.2 | B8: Redondear el monto antes de validarlo contra cero | D8: Equipo | E8: Hecho
A9: T-31.3 | B9: Acotar la fecha del movimiento entre el año 2000 y hoy | D9: Equipo | E9: Hecho
A10: T-31.4 | B10: Corregir el cálculo de la fecha para que no dependa de la zona horaria | D10: Equipo | E10: Hecho
A11: T-31.5 | B11: Reactivar los tipos junto con su categoría | D11: Equipo | E11: Hecho
A12: T-31.6 | B12: Impedir usar un tipo cuya categoría está desactivada | D12: Equipo | E12: Hecho
A13: HU-32 | B13: Como equipo quiero renombrar el dominio de cooperativas a empresas para que el sistema hable el idioma del público nuevo. | C13: Gestión de Empresas | D13: Equipo | E13: Hecho
A14: T-32.1 | B14: Renombrar las tablas y columnas en el script de base de datos | D14: Equipo | E14: Hecho
A15: T-32.2 | B15: Renombrar el rol de administrador de empresa | D15: Equipo | E15: Hecho
A16: T-32.3 | B16: Renombrar modelos, controladores, rutas y vistas | D16: Equipo | E16: Hecho
A17: T-32.4 | B17: Actualizar los datos de prueba con empresas y vocabulario acorde | D17: Equipo | E17: Hecho
A18: T-32.5 | B18: Verificar los circuitos completos después del renombrado | D18: Equipo | E18: Hecho
A19: HU-33 | B19: Como administrador de la plataforma quiero usar mi panel desde el celular para aprobar empresas donde esté. | C19: Calidad, UX y Documentación | D19: Equipo | E19: Hecho
A20: T-33.1 | B20: Escribir la hoja de estilos propia del panel de plataforma | D20: Equipo | E20: Hecho
A21: T-33.2 | B21: Adaptar el menú lateral a pantallas chicas | D21: Equipo | E21: Hecho
A22: T-33.3 | B22: Verificar que el escritorio no cambie | D22: Equipo | E22: Hecho
A23: HU-34 | B23: Como administrador de la empresa quiero activar sólo los módulos que mi empresa usa para no ver funciones que no necesito. | C23: Configuración de Módulos | D23: Equipo | E23: Hecho
A24: T-34.1 | B24: Crear la tabla de módulos activos por empresa | D24: Equipo | E24: Hecho
A25: T-34.2 | B25: Definir el conjunto de módulos disponibles | D25: Equipo | E25: Hecho
A26: T-34.3 | B26: Programar los endpoints de consulta y actualización | D26: Equipo | E26: Hecho
A27: T-34.4 | B27: Diseñar la pantalla de configuración de módulos | D27: Equipo | E27: Hecho
A28: T-34.5 | B28: Mostrar en el menú sólo los módulos activos | D28: Equipo | E28: Hecho
A29: HU-35 | B29: Como sistema quiero rechazar los pedidos a módulos desactivados para que no se pueda entrar por fuera del menú. | C29: Configuración de Módulos | D29: Equipo | E29: Hecho
A30: T-35.1 | B30: Programar el middleware de módulo activo | D30: Equipo | E30: Hecho
A31: T-35.2 | B31: Aplicarlo a las rutas de movimientos y categorías | D31: Equipo | E31: Hecho
A32: T-35.3 | B32: Mostrar en pantalla un aviso claro cuando el módulo está apagado | D32: Equipo | E32: Hecho
A33: T-35.4 | B33: Distinguir el aviso de módulo apagado del de falta de permiso | D33: Equipo | E33: Hecho
A34: T-35.5 | B34: Probar el acceso con el módulo apagado | D34: Equipo | E34: Hecho
A35: HU-36 | B35: Como empresa nueva quiero empezar con una configuración razonable para no tener que definir todo antes de usar el sistema. | C35: Configuración de Módulos | D35: Equipo | E35: Hecho
A36: T-36.1 | B36: Definir el conjunto de módulos y categorías iniciales | D36: Equipo | E36: Hecho
A37: T-36.2 | B37: Programar la carga automática al aprobar la empresa | D37: Equipo | E37: Hecho
A38: T-36.3 | B38: Dejar la configuración escrita en la base, no deducida del catálogo | D38: Equipo | E38: Hecho
A39: T-36.4 | B39: Evitar que una segunda aprobación duplique o pise lo ya configurado | D39: Equipo | E39: Hecho
A40: T-36.5 | B40: Probar el alta de una empresa nueva de punta a punta | D40: Equipo | E40: Hecho
C42: AVANCE DEL SPRINT (tareas terminadas) | E42: =TEXT(SUMPRODUCT((LEFT(A6:A40,2)="T-")*(E6:E40="Hecho"))/SUMPRODUCT((LEFT(A6:A40,2)="T-")*1),"0%")

Sheet Sprint 07
A1: Sprint 07 · CooperApp
A2: Período: 21/09 al 27/09 | Estado: Cerrado
A3: Objetivo del sprint: Abrir el módulo de Productos: que cada empresa arme su propio árbol de categorías y subcategorías y cargue su catálogo.
A5: ID | B5: Historia de usuario / Tarea | C5: Épica | D5: Responsable | E5: Estado
A6: HU-37 | B6: Como administrador quiero definir categorías y subcategorías de productos para organizar el catálogo a mi manera. | C6: Productos y Stock | D6: Equipo | E6: Hecho
A7: T-37.1 | B7: Crear las tablas de categorías y subcategorías de producto | D7: Equipo | E7: Hecho
A8: T-37.2 | B8: Programar los endpoints de alta, edición y cambio de estado | D8: Equipo | E8: Hecho
A9: T-37.3 | B9: Diseñar la pantalla del árbol de categorías | D9: Equipo | E9: Hecho
A10: T-37.4 | B10: Aplicar la baja y el alta en cascada, como en las categorías de movimientos | D10: Equipo | E10: Hecho
A11: HU-38 | B11: Como operador quiero cargar los productos de mi empresa para tener el catálogo completo. | C11: Productos y Stock | D11: Equipo | E11: Hecho
A12: T-38.1 | B12: Crear la tabla de productos | D12: Equipo | E12: Hecho
A13: T-38.2 | B13: Programar el alta, la edición y la baja lógica | D13: Equipo | E13: Hecho
A14: T-38.3 | B14: Diseñar el listado y el formulario de producto | D14: Equipo | E14: Hecho
A15: T-38.4 | B15: Validar el nombre único por empresa | D15: Equipo | E15: Hecho
A16: HU-39 | B16: Como operador quiero definir el stock mínimo de cada producto para saber cuándo reponer. | C16: Productos y Stock | D16: Equipo | E16: Hecho
A17: T-39.1 | B17: Agregar el stock mínimo al modelo de producto | D17: Equipo | E17: Hecho
A18: T-39.2 | B18: Agregar el campo en el formulario | D18: Equipo | E18: Hecho
A19: HU-40 | B19: Como usuario quiero buscar y filtrar el catálogo para encontrar un producto rápido. | C19: Productos y Stock | D19: Equipo | E19: Hecho
A20: T-40.1 | B20: Programar la búsqueda y los filtros | D20: Equipo | E20: Hecho
A21: T-40.2 | B21: Diseñar los controles en la pantalla | D21: Equipo | E21: Hecho
A22: T-40.3 | B22: Validar el catálogo en ancho de celular | D22: Equipo | E22: Hecho
C24: AVANCE DEL SPRINT (tareas terminadas) | E24: =TEXT(SUMPRODUCT((LEFT(A6:A22,2)="T-")*(E6:E22="Hecho"))/SUMPRODUCT((LEFT(A6:A22,2)="T-")*1),"0%")

Sheet Sprint 08
A1: Sprint 08 · CooperApp
A2: Período: 28/09 al 04/10 | Estado: Cerrado
A3: Objetivo del sprint: Cerrar el módulo de Productos con el control de existencias: motivos configurables, registro de movimientos de stock y aviso de faltantes.
A5: ID | B5: Historia de usuario / Tarea | C5: Épica | D5: Responsable | E5: Estado
A6: HU-41 | B6: Como administrador quiero definir los motivos de movimiento de stock para adaptarlos a cómo trabaja mi empresa. | C6: Productos y Stock | D6: Equipo | E6: Hecho
A7: T-41.1 | B7: Crear la tabla de motivos con su impacto en stock y en dinero | D7: Equipo | E7: Hecho
A8: T-41.2 | B8: Cargar los motivos iniciales: compra, venta, consumo, pérdida, robo y ajuste | D8: Equipo | E8: Hecho
A9: T-41.3 | B9: Programar los endpoints de gestión de motivos | D9: Equipo | E9: Hecho
A10: T-41.4 | B10: Diseñar la pantalla de motivos | D10: Equipo | E10: Hecho
A11: HU-42 | B11: Como operador quiero registrar entradas y salidas de stock para mantener las existencias al día. | C11: Productos y Stock | D11: Equipo | E11: Hecho
A12: T-42.1 | B12: Crear la tabla de movimientos de stock | D12: Equipo | E12: Hecho
A13: T-42.2 | B13: Programar el endpoint de registro | D13: Equipo | E13: Hecho
A14: T-42.3 | B14: Calcular la existencia actual a partir de los movimientos | D14: Equipo | E14: Hecho
A15: T-42.4 | B15: Diseñar el formulario de movimiento de stock | D15: Equipo | E15: Hecho
A16: HU-43 | B16: Como usuario quiero ver el stock actual y el historial de cada producto para saber qué pasó con él. | C16: Productos y Stock | D16: Equipo | E16: Hecho
A17: T-43.1 | B17: Diseñar la pantalla de existencias | D17: Equipo | E17: Hecho
A18: T-43.2 | B18: Programar el historial filtrable | D18: Equipo | E18: Hecho
A19: T-43.3 | B19: Mostrar quién registró cada movimiento | D19: Equipo | E19: Hecho
A20: HU-44 | B20: Como usuario quiero que me avisen cuando un producto queda por debajo del mínimo para reponer a tiempo. | C20: Productos y Stock | D20: Equipo | E20: Hecho
A21: T-44.1 | B21: Programar la consulta de faltantes | D21: Equipo | E21: Hecho
A22: T-44.2 | B22: Reemplazar el bloque de alertas de stock del dashboard | D22: Equipo | E22: Hecho
A23: T-44.3 | B23: Diseñar el indicador visual de faltante | D23: Equipo | E23: Hecho
A24: HU-45 | B24: Como tesorero quiero que un movimiento de stock con impacto económico me ofrezca registrar el dinero para no cargar dos veces. | C24: Productos y Stock | D24: Equipo | E24: Hecho
A25: T-45.1 | B25: Programar la propuesta de movimiento económico según el motivo | D25: Equipo | E25: Hecho
A26: T-45.2 | B26: Diseñar el paso de confirmación | D26: Equipo | E26: Hecho
A27: T-45.3 | B27: Dejar registrado el vínculo entre ambos movimientos | D27: Equipo | E27: Hecho
A28: T-45.4 | B28: Probar que no se dupliquen registros | D28: Equipo | E28: Hecho
A29: HU-46 | B29: Como operador quiero anular un movimiento de stock cargado por error para corregir sin perder el historial. | C29: Productos y Stock | D29: Equipo | E29: Hecho
A30: T-46.1 | B30: Programar la anulación lógica del movimiento de stock | D30: Equipo | E30: Hecho
A31: T-46.2 | B31: Verificar que la existencia se recalcule correctamente | D31: Equipo | E31: Hecho
C33: AVANCE DEL SPRINT (tareas terminadas) | E33: =TEXT(SUMPRODUCT((LEFT(A6:A31,2)="T-")*(E6:E31="Hecho"))/SUMPRODUCT((LEFT(A6:A31,2)="T-")*1),"0%")

Sheet Sprint 09
A1: Sprint 09 · CooperApp
A2: Período: 05/10 al 11/10 | Estado: En curso
A3: Objetivo del sprint: Emparejar la base ANTES de duplicarla, y recién entonces abrir Servicios. El orden importa: Servicios copia las pantallas de Productos, así que cada nombre, cada tabla que no entra en el celular y cada pantalla de configuración mal ubicada que quede sin arreglar se copia a un lugar más. Primero el vocabulario, el celular y la configuración; después el módulo nuevo, que es un producto sin stock.
A5: ID | B5: Historia de usuario / Tarea | C5: Épica | D5: Responsable | E5: Estado
A6: HU-83 | B6: Como empresa nueva quiero poder registrarme y entrar sin trabarme para empezar a usar el sistema. | C6: Calidad, UX y Documentación | D6: Equipo | E6: Hecho
A7: T-83.1 | B7: Sacar la matrícula del registro, del perfil y de la base | D7: Equipo | E7: Hecho
A8: T-83.2 | B8: Que el formulario de registro no se cierre ni se borre cuando hay un error | D8: Equipo | E8: Hecho
A9: T-83.3 | B9: Marcar los campos obligatorios y nombrar el que falta | D9: Equipo | E9: Hecho
A10: T-83.4 | B10: Mandar al administrador de la plataforma a su panel al iniciar sesión | D10: Equipo | E10: Hecho
A11: T-83.5 | B11: Llevar los módulos sin pantalla a un aviso de 'en construcción' | D11: Equipo | E11: Hecho
A12: T-83.6 | B12: Explicarle al operador qué hacer si falta la categoría del producto | D12: Equipo | E12: Hecho
A13: HU-89 | B13: Como empresa quiero que dos personas puedan trabajar al mismo tiempo sin que los números queden mal. | C13: Calidad, UX y Documentación | D13: Equipo | E13: Hecho
A14: T-89.1 | B14: Trabar la fila del producto antes de contar la existencia | D14: Equipo | E14: Hecho
A15: T-89.2 | B15: Hacer el control y el alta del movimiento de stock en una sola transacción | D15: Equipo | E15: Hecho
A16: T-89.3 | B16: Hacer lo mismo con el movimiento de dinero de una venta | D16: Equipo | E16: Hecho
A17: T-89.4 | B17: Corregir la marca del cobro para que mire si el movimiento sigue vigente | D17: Equipo | E17: Hecho
A18: T-89.5 | B18: No revivir en cascada lo que el administrador dio de baja a propósito | D18: Equipo | E18: Hecho
A19: T-89.6 | B19: Validar el largo de los textos y pedir modo estricto a la base | D19: Equipo | E19: Hecho
A20: T-89.7 | B20: Devolver JSON en vez del stack trace cuando el pedido viene mal | D20: Equipo | E20: Hecho
A21: HU-84 | B21: Como usuario quiero que cada cosa se llame siempre igual para aprender una vez y no tener que adivinar. | C21: Calidad, UX y Documentación | D21: Equipo | E21: Hecho
A22: T-84.1 | B22: Decidir los nombres en grupo (naturaleza, categorías, anular/dar de baja) | D22: Equipo | E22: Hecho
A23: T-84.2 | B23: Reemplazar 'naturaleza' por dos botones: entró o salió | D23: Equipo | E23: Hecho
A24: T-84.3 | B24: Ponerle apellido a las dos pantallas: categorías de movimientos y de productos | D24: Equipo | E24: Hecho
A25: T-84.4 | B25: Unificar anular / dar de baja / desactivar en dos palabras y dos íconos | D25: Equipo | E25: Hecho
A26: T-84.5 | B26: Renombrar los movimientos de stock como entradas y salidas | D26: Equipo | E26: Hecho
A27: T-84.6 | B27: Aplicar el mismo vocabulario a los mensajes que devuelve el servidor | D27: Equipo | E27: Hecho
A28: HU-85 | B28: Como operador quiero ver en el celular la columna que me importa para no tener que arrastrar la tabla de costado. | C28: Calidad, UX y Documentación | D28: Equipo | E28: Hecho
A29: T-85.1 | B29: Escribir el patrón de tarjetas en una hoja compartida, para que lo use toda la app | D29: Equipo | E29: Hecho
A30: T-85.2 | B30: Convertir los listados en tarjetas por debajo de 768 px | D30: Equipo | E30: Hecho
A31: T-85.3 | B31: Compactar el encabezado en celular con un botón de menú | D31: Equipo | E31: Hecho
A32: T-85.4 | B32: Validar en 375 px que no quede scroll horizontal | D32: Equipo | E32: Hecho
A33: HU-86 | B33: Como administrador quiero encontrar la configuración en un solo lugar para no buscarla abajo de mi nombre. | C33: Calidad, UX y Documentación | D33: Equipo | E33: Hecho
A34: T-86.1 | B34: Agrupar las cuatro pantallas de configuración en el menú principal | D34: Equipo | E34: Hecho
A35: T-86.2 | B35: Dejar en el menú del usuario sólo lo personal y cerrar sesión | D35: Equipo | E35: Hecho
A36: T-86.3 | B36: Mover el acceso a motivos desde Productos a Stock | D36: Equipo | E36: Hecho
A37: HU-47 | B37: Como administrador quiero cargar los servicios que presta o contrata mi empresa para registrarlos igual que los productos. | C37: Servicios | D37: Equipo | E37: Hecho
A38: T-47.1 | B38: Reutilizar el modelo de productos agregando la distinción de servicio | D38: Equipo | E38: Hecho
A39: T-47.2 | B39: Programar el alta, la edición y la baja lógica | D39: Equipo | E39: Hecho
A40: T-47.3 | B40: Diseñar la pantalla de servicios | D40: Equipo | E40: Hecho
A41: T-47.4 | B41: Verificar que los servicios no lleven existencias | D41: Equipo | E41: Hecho
...

Sheet Sprint 10
A1: Sprint 10 · CooperApp
A2: Período: 12/10 al 18/10 | Estado: En curso
A3: Objetivo del sprint: Entregar los reportes por período, categoría, producto y servicio, con exportación para que la empresa pueda compartirlos fuera del sistema.
A5: ID | B5: Historia de usuario / Tarea | C5: Épica | D5: Responsable | E5: Estado
A6: HU-51 | B6: Como empresa quiero un reporte por período para revisar la actividad de un mes o un rango de fechas. | C6: Reportes | D6: Equipo | E6: Hecho
A7: T-51.1 | B7: Programar el endpoint de reporte por período | D7: Equipo | E7: Hecho
A8: T-51.2 | B8: Diseñar la pantalla de reportes | D8: Equipo | E8: Hecho
A9: T-51.3 | B9: Implementar el selector de fechas | D9: Equipo | E9: Hecho
A10: T-51.4 | B10: Verificar la consistencia de los totales | D10: Equipo | E10: Hecho
A11: HU-52 | B11: Como empresa quiero reportes por categoría, producto y servicio para analizar en detalle. | C11: Reportes | D11: Equipo | E11: Hecho
A12: T-52.1 | B12: Programar el reporte por categoría | D12: Equipo | E12: Hecho
A13: T-52.2 | B13: Programar el reporte por producto | D13: Equipo | E13: Hecho
A14: T-52.3 | B14: Programar el reporte por servicio | D14: Equipo | E14: Hecho
A15: HU-53 | B15: Como empresa quiero ver cuánto perdí en mercadería para dimensionar las pérdidas y los faltantes. | C15: Reportes | D15: Equipo | E15: Hecho
A16: T-53.1 | B16: Programar la valorización de las salidas sin impacto económico | D16: Equipo | E16: Hecho
A17: T-53.2 | B17: Diseñar el reporte de pérdidas | D17: Equipo | E17: Hecho
A18: T-53.3 | B18: Verificar que no se sumen al balance | D18: Equipo | E18: Hecho
A19: HU-54 | B19: Como empresa quiero descargar el reporte para presentarlo o compartirlo. | C19: Reportes | D19: Equipo | E19: Hecho
A20: T-54.1 | B20: Programar la exportación a CSV | D20: Equipo | E20: Hecho
A21: T-54.2 | B21: Programar la exportación a PDF | D21: Equipo | E21: Hecho
A22: T-54.3 | B22: Nombrar el archivo con el período | D22: Equipo | E22: Hecho
C24: AVANCE DEL SPRINT (tareas terminadas) | E24: =TEXT(SUMPRODUCT((LEFT(A6:A22,2)="T-")*(E6:E22="Hecho"))/SUMPRODUCT((LEFT(A6:A22,2)="T-")*1),"0%")

Sheet Sprint 11
A1: Sprint 11 · CooperApp
A2: Período: 19/10 al 25/10 | Estado: Planificado
A3: Objetivo del sprint: Abrir el segundo eje del proyecto: que las empresas publiquen sus necesidades y lo que pueden ofrecer, para habilitar la articulación entre ellas.
A5: ID | B5: Historia de usuario / Tarea | C5: Épica | D5: Responsable | E5: Estado
A6: HU-55 | B6: Como empresa quiero publicar mis necesidades para que otras empresas puedan resolverlas. | C6: Articulación entre Empresas | E6: Pendiente
A7: T-55.1 | B7: Crear las tablas de necesidades y categorías de articulación | E7: Pendiente
A8: T-55.2 | B8: Definir las categorías: espacio, vehículo, formación, insumos y servicios | E8: Pendiente
A9: T-55.3 | B9: Programar el alta, la edición y la baja de necesidades | E9: Pendiente
A10: T-55.4 | B10: Diseñar la pantalla de publicaciones | E10: Pendiente
A11: HU-56 | B11: Como empresa quiero publicar lo que puedo ofrecer para poner en valor mis capacidades. | C11: Articulación entre Empresas | E11: Pendiente
A12: T-56.1 | B12: Crear la tabla de ofertas | E12: Pendiente
A13: T-56.2 | B13: Programar el alta, la edición y la baja de ofertas | E13: Pendiente
A14: HU-57 | B14: Como empresa quiero ver las necesidades y ofertas de otras empresas para encontrar oportunidades. | C14: Articulación entre Empresas | E14: Pendiente
A15: T-57.1 | B15: Programar el listado entre empresas aprobadas | E15: Pendiente
A16: T-57.2 | B16: Implementar el filtro por categoría y localidad | E16: Pendiente
A17: HU-58 | B17: Como empresa quiero controlar qué datos de contacto se muestran para cuidar mi información. | C17: Articulación entre Empresas | E17: Pendiente
A18: T-58.1 | B18: Definir y programar la configuración de datos visibles | E18: Pendiente
C20: AVANCE DEL SPRINT (tareas terminadas) | E20: =TEXT(SUMPRODUCT((LEFT(A6:A18,2)="T-")*(E6:E18="Hecho"))/SUMPRODUCT((LEFT(A6:A18,2)="T-")*1),"0%")

Sheet Sprint 12
A1: Sprint 12 · CooperApp
A2: Período: 26/10 al 01/11 | Estado: Planificado
A3: Objetivo del sprint: Completar la articulación con la detección automática de coincidencias y el aviso de match, que es la funcionalidad diferencial del producto.
A5: ID | B5: Historia de usuario / Tarea | C5: Épica | D5: Responsable | E5: Estado
A6: HU-59 | B6: Como empresa quiero que el sistema detecte coincidencias entre mis necesidades y las ofertas de otras para no tener que buscarlas. | C6: Articulación entre Empresas | E6: Pendiente
A7: T-59.1 | B7: Definir los criterios de coincidencia | E7: Pendiente
A8: T-59.2 | B8: Programar el algoritmo de coincidencia | E8: Pendiente
A9: T-59.3 | B9: Programar el endpoint de coincidencias | E9: Pendiente
A10: HU-60 | B10: Como empresa quiero recibir un aviso cuando haya una coincidencia para actuar a tiempo. | C10: Articulación entre Empresas | E10: Pendiente
A11: T-60.1 | B11: Crear la tabla de avisos | E11: Pendiente
A12: T-60.2 | B12: Reemplazar el bloque de matches del dashboard | E12: Pendiente
A13: T-60.3 | B13: Programar la marca de leído | E13: Pendiente
A14: HU-61 | B14: Como empresa quiero contactar a la otra empresa cuando hay una coincidencia para concretar la articulación. | C14: Articulación entre Empresas | E14: Pendiente
A15: T-61.1 | B15: Mostrar los datos de contacto habilitados | E15: Pendiente
A16: T-61.2 | B16: Registrar los contactos realizados | E16: Pendiente
A17: HU-62 | B17: Como equipo quiero probar el módulo de articulación para entregarlo funcionando. | C17: Calidad, UX y Documentación | E17: Pendiente
A18: T-62.1 | B18: Escribir y ejecutar los casos de prueba de coincidencia | E18: Pendiente
C20: AVANCE DEL SPRINT (tareas terminadas) | E20: =TEXT(SUMPRODUCT((LEFT(A6:A18,2)="T-")*(E6:E18="Hecho"))/SUMPRODUCT((LEFT(A6:A18,2)="T-")*1),"0%")

Sheet Sprint 13
A1: Sprint 13 · CooperApp
A2: Período: 02/11 al 08/11 | Estado: Planificado
A3: Objetivo del sprint: Cierre del ciclo: definir la identidad del producto, terminar de ajustar la interfaz, probar de punta a punta y documentar para la continuidad del proyecto. Queda más liviano que en la planificación anterior porque el vocabulario, el celular y la configuración se adelantaron al Sprint 09, donde hacían falta.
A5: ID | B5: Historia de usuario / Tarea | C5: Épica | D5: Responsable | E5: Estado
A6: HU-63 | B6: Como equipo quiero definir el nombre y la identidad del producto para que acompañen al público al que apunta. | C6: Calidad, UX y Documentación | E6: Pendiente
A7: T-63.1 | B7: Definir el nombre del producto con el equipo | E7: Pendiente
A8: T-63.2 | B8: Aplicarlo en la interfaz y en los títulos de las pantallas | E8: Pendiente
A9: T-63.3 | B9: Renombrar la base de datos y el repositorio | E9: Pendiente
A10: T-63.4 | B10: Actualizar la documentación y la validación de idea | E10: Pendiente
A11: HU-64 | B11: Como usuario con poca experiencia digital quiero una interfaz clara para poder usar el sistema sin ayuda. | C11: Calidad, UX y Documentación | E11: Pendiente
A12: T-64.1 | B12: Revisar los textos y rótulos de todas las pantallas | E12: Pendiente
A13: T-64.2 | B13: Agregar ayudas contextuales | E13: Pendiente
A14: T-64.3 | B14: Revisar el contraste y el tamaño de la tipografía | E14: Pendiente
A15: T-64.4 | B15: Validar la interfaz con un usuario real | E15: Pendiente
A16: T-64.5 | B16: Decidir con usuarios si el resultado por servicio vive en Movimientos o en Reportes | E16: Pendiente
A17: HU-87 | B17: Como tesorero quiero cargar un movimiento en menos pasos para no contestar tres preguntas encadenadas. | C17: Calidad, UX y Documentación | E17: Pendiente
A18: T-87.1 | B18: Reemplazar los tres desplegables encadenados por uno solo | E18: Pendiente
A19: T-87.2 | B19: Permitir corregir un movimiento anulado sin escribirlo de nuevo | E19: Pendiente
A20: HU-88 | B20: Como usuario quiero que las pantallas vacías me digan por dónde empezar en vez de culpar a un filtro que no toqué. | C20: Calidad, UX y Documentación | E20: Pendiente
A21: T-88.1 | B21: Separar el listado vacío del listado filtrado en los cuatro listados | E21: Pendiente
A22: T-88.2 | B22: Agregar un bloque de primeros pasos al panel de una empresa nueva | E22: Pendiente
A23: T-88.3 | B23: Poner 'Sin acceso' en los indicadores que el rol no puede ver | E23: Pendiente
A24: HU-65 | B24: Como usuario quiero usar todo el sistema desde el celular para trabajar donde estoy. | C24: Calidad, UX y Documentación | E24: Pendiente
A25: T-65.1 | B25: Colapsar los filtros detrás de un botón en las pantallas de listado | E25: Pendiente
A26: T-65.2 | B26: Revisar las pantallas de los módulos nuevos en ancho de celular | E26: Pendiente
A27: T-65.3 | B27: Validar en Chrome y en un segundo navegador | E27: Pendiente
A28: T-65.4 | B28: Validar en un celular real | E28: Pendiente
A29: HU-66 | B29: Como equipo quiero dejar el proyecto documentado para poder continuarlo el año próximo. | C29: Calidad, UX y Documentación | E29: Pendiente
A30: T-66.1 | B30: Escribir el README con las instrucciones de instalación | E30: Pendiente
A31: T-66.2 | B31: Escribir el manual de usuario básico | E31: Pendiente
A32: T-66.3 | B32: Documentar el modelo de datos | E32: Pendiente
A33: T-66.4 | B33: Documentar el diseño de los módulos que quedaron sin implementar | E33: Pendiente
A34: HU-67 | B34: Como equipo quiero probar el sistema completo para entregar una versión estable. | C34: Calidad, UX y Documentación | E34: Pendiente
A35: T-67.1 | B35: Ejecutar la batería de pruebas de punta a punta | E35: Pendiente
A36: T-67.2 | B36: Corregir los errores detectados | E36: Pendiente
A37: T-67.3 | B37: Unificar la carga del encabezado en un archivo compartido | E37: Pendiente
C39: AVANCE DEL SPRINT (tareas terminadas) | E39: =TEXT(SUMPRODUCT((LEFT(A6:A37,2)="T-")*(E6:E37="Hecho"))/SUMPRODUCT((LEFT(A6:A37,2)="T-")*1),"0%")

Sheet Incremento
A1: Incremento por Sprint · CooperApp
A2: Qué queda funcionando al cerrar cada sprint y qué se le puede mostrar a un usuario real
A4: Sprint | B4: Período | C4: Incremento funcional al cerrar el sprint | D4: Qué se le puede mostrar a un usuario real | E4: Dependencias a resolver antes
A5: Sprint 01 | B5: Cerrado · entrega anterior | C5: Una empresa puede registrarse y el administrador de la plataforma puede aprobarla o rechazarla. | D5: El circuito de alta completo: una empresa se registra y queda pendiente hasta que la plataforma la habilita. | E5: Modelo de datos inicial · conexión a MySQL.
A6: Sprint 02 | B6: Cerrado · entrega anterior | C6: Los usuarios pueden iniciar sesión, cambiar su contraseña temporal, y el administrador de cada empresa puede dar de alta a su equipo con roles diferenciados. | D6: El primer ingreso de un usuario nuevo: entra con su DNI, elige su contraseña y ve sólo lo que le corresponde. | E6: Manejo de sesiones · roles cargados en la base.
A7: Sprint 03 | B7: 24/08 al 30/08 | C7: La empresa puede mantener sus propios datos actualizados, y las contraseñas se recuperan sin depender del correo: cada administrador resetea a los usuarios que le corresponden. | D7: Un usuario que perdió su contraseña la recupera en el momento, con el administrador al lado. | E7: Estructura de roles consistente · migración del esquema de base de datos.
A8: Sprint 04 | B8: 31/08 al 06/09 | C8: La empresa puede definir su propia estructura de categorías y tipos de ingresos y egresos. | D8: El referente de la empresa carga sus categorías reales y valida que el esquema le sirve. | E8: Tablas de categorías y tipos · baja lógica en cascada.
A9: Sprint 05 | B9: 07/09 al 13/09 | C9: La empresa registra, consulta y corrige ingresos y egresos, y ve su balance del mes con la comparación contra el mes anterior. Es el primer entregable que resuelve el problema central. | D9: Un tesorero carga los movimientos reales de una semana y ve el balance actualizarse. | E9: Estructura de categorías terminada · rediseño de la tabla de movimientos.
A10: Sprint 06 | B10: 14/09 al 20/09 | C10: El sistema habla en lenguaje de empresas, está corregido de la deuda detectada en la revisión, y cada empresa activa sólo los módulos que va a usar. | D10: El administrador entra a configuración, apaga los módulos que no necesita y el menú se reduce a lo suyo. | E10: Decisión del equipo sobre el alcance nuevo · renombrado del dominio terminado.
A11: Sprint 07 | B11: 21/09 al 27/09 | C11: La empresa arma su propio árbol de categorías y subcategorías de productos y carga su catálogo. | D11: El catálogo cargado con las categorías reales de la empresa, por ejemplo Alimentos y Perecederos. | E11: Módulo de productos activado · tablas de catálogo.
A12: Sprint 08 | B12: 28/09 al 04/10 | C12: El stock se mueve con motivos configurables, se actualiza solo, avisa de faltantes y ofrece registrar el movimiento de dinero cuando corresponde. | D12: Registrar una venta y ver cómo descuenta el stock y propone el ingreso, sin cargar dos veces. | E12: Catálogo cargado · motivos definidos con su impacto en stock y en dinero.
A13: Sprint 09 | B13: 05/10 al 11/10 | C13: La empresa registra sus servicios y los vincula con los movimientos de dinero, y ve cuánto le deja cada uno. | D13: El resumen por servicio: qué servicios sostienen la empresa y cuáles no. | E13: Modelo de productos terminado · módulo de servicios activado.
A14: Sprint 10 | B14: 12/10 al 18/10 | C14: La empresa genera reportes por período, categoría, producto y servicio, ve sus pérdidas valorizadas y puede descargar todo. | D14: Un reporte mensual descargado, listo para presentar a la dirección o al contador. | E14: Datos suficientes cargados · librería de generación de PDF.
